F
======================================================================
FAIL: Test function for to_celsius
----------------------------------------------------------------------
Traceback (most recent call last):
  File "c:\Python25\Lib\site-packages\nose\case.py", line 202, in runTest
    self.test(*self.arg)
  File "assert3.py", line 6, in test_to_celsius
    assert to_celsius(100) == 37.8, 'Returning an unrounded result'
AssertionError: Returning an unrounded result

----------------------------------------------------------------------
Ran 1 test in 0.000s

FAILED (failures=1)
